#VRML_SIM R2019a utf8
WorldInfo {
}
Viewpoint {
  orientation 0.032187308439112126 0.999481758938836 0.00043671956228187765 4.776031951692978
  position -0.9729108762430266 0.30130153863676634 0.17028972126696937
}
TexturedBackground {
}
TexturedBackgroundLight {
}
Floor {
}
Solid {
  rotation 1 0 0 0
  children [
    DEF COLUMPIO Group {
      children [
        DEF A Group {
          children [
            Transform {
              translation 0 0.19 0
              rotation 0 0 1 0.3926996938995747
              children [
                DEF SH_AL Shape {
                  appearance DEF BLUE PBRAppearance {
                    baseColor 0.4470588235294118 0.6235294117647059 0.8117647058823529
                    roughness 1
                    metalness 0
                  }
                  geometry DEF BASE Cylinder {
                    height 0.4
                    radius 0.02
                  }
                }
              ]
            }
            Transform {
              translation -0.18 0.19 0
              rotation 0 0 1 -0.393
              children [
                DEF SH_AR Shape {
                  appearance DEF BLUE PBRAppearance {
                    baseColor 0.4470588235294118 0.6235294117647059 0.8117647058823529
                    roughness 1
                    metalness 0
                  }
                  geometry DEF BASE Cylinder {
                    height 0.4
                    radius 0.02
                  }
                }
              ]
            }
            Transform {
              translation -0.09 0.2 0
              rotation 0 0 1 1.5707996938995747
              children [
                Shape {
                  appearance USE BLUE
                  geometry DEF SH_MIDDLE Cylinder {
                    height 0.19
                    radius 0.018
                  }
                }
              ]
            }
          ]
        }
        DEF AI Group {
          children [
            Transform {
              translation 0 0 0.36
              rotation 0 0 1 6.283185307179586
              children [
                Transform {
                  translation -0.09 0.39 -0.18
                  rotation 1 0 0 1.5708003061004252
                  children [
                    Shape {
                      appearance USE BLUE
                      geometry USE BASE
                    }
                  ]
                }
                USE A
              ]
            }
          ]
        }
      ]
    }
    HingeJoint {
      jointParameters HingeJointParameters {
        axis 0 0 1
        anchor -0.09 0.35 0.18
      }
      endPoint Solid {
        rotation 0 0 1 0
        children [
          Group {
            children [
              Transform {
                translation -0.09 0.32 0.18
                children [
                  Shape {
                    appearance DEF YELLOW PBRAppearance {
                      baseColor 0.9882352941176471 0.9137254901960784 0.30980392156862746
                      roughness 1
                      metalness 0
                    }
                    geometry DEF CYLINDER Cylinder {
                      height 0.06
                      radius 0.02
                    }
                  }
                ]
              }
              Transform {
                translation -0.09 0.28 0.18
                children [
                  Shape {
                    appearance USE YELLOW
                    geometry Sphere {
                      radius 0.03
                    }
                  }
                ]
              }
            ]
          }
        ]
        physics Physics {
        }
      }
    }
    HingeJoint {
      jointParameters HingeJointParameters {
        axis 0 1 0
        anchor -0.09000000000000001 0.37 0.18
      }
      endPoint Solid {
        translation -0.09 0.36 0.18
        rotation 0 -1 0 0.00017131999239528576
        children [
          Shape {
            appearance DEF GREEN PBRAppearance {
              baseColor 0.5411764705882353 0.8862745098039215 0.20392156862745098
              roughness 1
              metalness 0
            }
            geometry DEF BOX Box {
              size 0.019999999999999997 0.02 0.2
            }
          }
        ]
        name "solid(1)"
        physics Physics {
        }
      }
    }
  ]
}
